{"level":"error","message":"提取原图片时出错: Command failed: python E:\\Code\\WSI\\BackEnd\\algorithm\\utils\\extractPng.py --slide_folder \"E:/Downloads/slides\" --slide_file_name \"2105274011_221716.svs\"\npython: can't open file 'E:\\Code\\WSI\\BackEnd\\algorithm\\utils\\extractPng.py': [Errno 2] No such file or directory\n","timestamp":"2025-04-30 11:50:31"}
{"level":"error","message":"提取原图片时出错: Command failed: python E:\\Code\\WSI\\BackEnd\\algorithm\\utils\\extractPng.py --slide_folder \"E:/Downloads/slides\" --slide_file_name \"2105274011_221716.svs\"\npython: can't open file 'E:\\Code\\WSI\\BackEnd\\algorithm\\utils\\extractPng.py': [Errno 2] No such file or directory\n","timestamp":"2025-04-30 12:09:28"}
{"level":"error","message":"提取原图片时出错: Command failed: python E:\\Code\\WSI\\BackEnd\\algorithm\\src\\extractPng.py --slide_folder \"E:/Downloads/slides\" --slide_file_name \"2105274011_221716.svs\"\nTraceback (most recent call last):\r\n  File \"E:\\Code\\WSI\\BackEnd\\algorithm\\src\\extractPng.py\", line 6, in <module>\r\n    from utils.myLogger import setup_logger\r\nModuleNotFoundError: No module named 'utils'\r\n","timestamp":"2025-04-30 12:11:45"}
{"level":"error","message":"提取原图片时出错: Command failed: python E:\\Code\\WSI\\BackEnd\\algorithm\\src\\extractPng.py --slide_folder \"E:/Downloads/slides\" --slide_file_name \"2105274011_221716.svs\"\nTraceback (most recent call last):\r\n  File \"E:\\Code\\WSI\\BackEnd\\algorithm\\src\\extractPng.py\", line 6, in <module>\r\n    from algorithm.utils.myLogger import setup_logger\r\nModuleNotFoundError: No module named 'algorithm'\r\n","timestamp":"2025-04-30 12:13:10"}
{"level":"error","message":"提取原图片时出错: Command failed: python E:\\Code\\WSI\\BackEnd\\algorithm\\src\\extractPng.py --slide_folder \"E:/Downloads/slides\" --slide_file_name \"2105274011_221716.svs\"\nTraceback (most recent call last):\r\n  File \"E:\\Code\\WSI\\BackEnd\\algorithm\\src\\extractPng.py\", line 6, in <module>\r\n    from ..utils.myLogger import setup_logger\r\nImportError: attempted relative import with no known parent package\r\n","timestamp":"2025-04-30 12:13:33"}
{"level":"error","message":"提取原图片时出错: Command failed: python E:\\Code\\WSI\\BackEnd\\algorithm\\src\\extractPng.py --slide_folder \"E:/Downloads/slides\" --slide_file_name \"2105274011_221716.svs\"\nTraceback (most recent call last):\r\n  File \"E:\\Code\\WSI\\BackEnd\\algorithm\\src\\extractPng.py\", line 8, in <module>\r\n    from utils.myLogger import setup_logger\r\nModuleNotFoundError: No module named 'utils'\r\n","timestamp":"2025-04-30 13:23:08"}
{"level":"error","message":"提取原图片时出错: Command failed: python E:\\Code\\WSI\\BackEnd\\algorithm\\src\\extractPng.py --slide_folder \"E:/Downloads/slides\" --slide_file_name \"2105274011_221716.svs\"\nTraceback (most recent call last):\r\n  File \"E:\\Code\\WSI\\BackEnd\\algorithm\\src\\extractPng.py\", line 9, in <module>\r\n    from utils.myLogger import setup_logger\r\nModuleNotFoundError: No module named 'utils'\r\n","timestamp":"2025-04-30 13:24:04"}
{"level":"error","message":"Python 脚本 error: Command failed: python E:\\Code\\WSI\\BackEnd\\algorithm\\main.py --slide_folder E:/Downloads/slides --slide_file_name 2001549007_101728.svs --isNormalized notNormalized\nTraceback (most recent call last):\r\n  File \"E:\\Code\\WSI\\BackEnd\\algorithm\\main.py\", line 113, in <module>\r\n    seg_patch(slide_folder, slide_file_name, patches_base_folder, model_patch_size, model_name, dict_name, isSegmented, isNormalized, justOriginSegmented)\r\n  File \"E:\\Code\\WSI\\BackEnd\\algorithm\\main.py\", line 68, in seg_patch\r\n    tumorEdge_file_name = edgeDetect(slide_folder,slide_file_name,res_dir,isNormalized)\r\n  File \"E:\\Code\\WSI\\BackEnd\\algorithm\\src\\edgeDetect.py\", line 53, in edgeDetect\r\n    df['y'] = df['patch'].str.split('_').str[0].astype(int)\r\n  File \"D:\\Develop\\AnaConda\\envs\\SURE\\lib\\site-packages\\pandas\\core\\generic.py\", line 6324, in astype\r\n    new_data = self._mgr.astype(dtype=dtype, copy=copy, errors=errors)\r\n  File \"D:\\Develop\\AnaConda\\envs\\SURE\\lib\\site-packages\\pandas\\core\\internals\\managers.py\", line 451, in astype\r\n    return self.apply(\r\n  File \"D:\\Develop\\AnaConda\\envs\\SURE\\lib\\site-packages\\pandas\\core\\internals\\managers.py\", line 352, in apply\r\n    applied = getattr(b, f)(**kwargs)\r\n  File \"D:\\Develop\\AnaConda\\envs\\SURE\\lib\\site-packages\\pandas\\core\\internals\\blocks.py\", line 511, in astype\r\n    new_values = astype_array_safe(values, dtype, copy=copy, errors=errors)\r\n  File \"D:\\Develop\\AnaConda\\envs\\SURE\\lib\\site-packages\\pandas\\core\\dtypes\\astype.py\", line 242, in astype_array_safe\r\n    new_values = astype_array(values, dtype, copy=copy)\r\n  File \"D:\\Develop\\AnaConda\\envs\\SURE\\lib\\site-packages\\pandas\\core\\dtypes\\astype.py\", line 187, in astype_array\r\n    values = _astype_nansafe(values, dtype, copy=copy)\r\n  File \"D:\\Develop\\AnaConda\\envs\\SURE\\lib\\site-packages\\pandas\\core\\dtypes\\astype.py\", line 138, in _astype_nansafe\r\n    return arr.astype(dtype, copy=True)\r\nValueError: invalid literal for int() with base 10: 'patch'\r\n","timestamp":"2025-04-30 20:12:35"}
{"level":"error","message":"Python 脚本 error: Command failed: python E:\\Code\\WSI\\BackEnd\\algorithm\\main.py --slide_folder E:/Downloads/slides --slide_file_name 1726363012.svs --isNormalized notNormalized --isSegmented True\nTraceback (most recent call last):\r\n  File \"E:\\Code\\WSI\\BackEnd\\algorithm\\main.py\", line 113, in <module>\r\n    seg_patch(slide_folder, slide_file_name, patches_base_folder, model_patch_size, model_name, dict_name, isSegmented, isNormalized, justOriginSegmented)\r\n  File \"E:\\Code\\WSI\\BackEnd\\algorithm\\main.py\", line 68, in seg_patch\r\n    tumorEdge_file_name = edgeDetect(slide_folder,slide_file_name,res_dir,isNormalized)\r\n  File \"E:\\Code\\WSI\\BackEnd\\algorithm\\src\\edgeDetect.py\", line 53, in edgeDetect\r\n    df['y'] = df['patch'].str.split('_').str[0].astype(int)\r\n  File \"D:\\Develop\\AnaConda\\envs\\SURE\\lib\\site-packages\\pandas\\core\\generic.py\", line 6324, in astype\r\n    new_data = self._mgr.astype(dtype=dtype, copy=copy, errors=errors)\r\n  File \"D:\\Develop\\AnaConda\\envs\\SURE\\lib\\site-packages\\pandas\\core\\internals\\managers.py\", line 451, in astype\r\n    return self.apply(\r\n  File \"D:\\Develop\\AnaConda\\envs\\SURE\\lib\\site-packages\\pandas\\core\\internals\\managers.py\", line 352, in apply\r\n    applied = getattr(b, f)(**kwargs)\r\n  File \"D:\\Develop\\AnaConda\\envs\\SURE\\lib\\site-packages\\pandas\\core\\internals\\blocks.py\", line 511, in astype\r\n    new_values = astype_array_safe(values, dtype, copy=copy, errors=errors)\r\n  File \"D:\\Develop\\AnaConda\\envs\\SURE\\lib\\site-packages\\pandas\\core\\dtypes\\astype.py\", line 242, in astype_array_safe\r\n    new_values = astype_array(values, dtype, copy=copy)\r\n  File \"D:\\Develop\\AnaConda\\envs\\SURE\\lib\\site-packages\\pandas\\core\\dtypes\\astype.py\", line 187, in astype_array\r\n    values = _astype_nansafe(values, dtype, copy=copy)\r\n  File \"D:\\Develop\\AnaConda\\envs\\SURE\\lib\\site-packages\\pandas\\core\\dtypes\\astype.py\", line 138, in _astype_nansafe\r\n    return arr.astype(dtype, copy=True)\r\nValueError: invalid literal for int() with base 10: 'patch'\r\n","timestamp":"2025-04-30 20:16:23"}
{"level":"error","message":"Python 脚本 error: Command failed: python E:\\Code\\WSI\\BackEnd\\algorithm\\main.py --slide_folder E:/Downloads/slides --slide_file_name 2004409012_141125.svs --isNormalized notNormalized\nTraceback (most recent call last):\r\n  File \"E:\\Code\\WSI\\BackEnd\\algorithm\\main.py\", line 113, in <module>\r\n    seg_patch(slide_folder, slide_file_name, patches_base_folder, model_patch_size, model_name, dict_name, isSegmented, isNormalized, justOriginSegmented)\r\n  File \"E:\\Code\\WSI\\BackEnd\\algorithm\\main.py\", line 68, in seg_patch\r\n    tumorEdge_file_name = edgeDetect(slide_folder,slide_file_name,res_dir,isNormalized)\r\n  File \"E:\\Code\\WSI\\BackEnd\\algorithm\\src\\edgeDetect.py\", line 53, in edgeDetect\r\n    df['y'] = df['patch'].str.split('_').str[0].astype(int)\r\n  File \"D:\\Develop\\AnaConda\\envs\\SURE\\lib\\site-packages\\pandas\\core\\generic.py\", line 6324, in astype\r\n    new_data = self._mgr.astype(dtype=dtype, copy=copy, errors=errors)\r\n  File \"D:\\Develop\\AnaConda\\envs\\SURE\\lib\\site-packages\\pandas\\core\\internals\\managers.py\", line 451, in astype\r\n    return self.apply(\r\n  File \"D:\\Develop\\AnaConda\\envs\\SURE\\lib\\site-packages\\pandas\\core\\internals\\managers.py\", line 352, in apply\r\n    applied = getattr(b, f)(**kwargs)\r\n  File \"D:\\Develop\\AnaConda\\envs\\SURE\\lib\\site-packages\\pandas\\core\\internals\\blocks.py\", line 511, in astype\r\n    new_values = astype_array_safe(values, dtype, copy=copy, errors=errors)\r\n  File \"D:\\Develop\\AnaConda\\envs\\SURE\\lib\\site-packages\\pandas\\core\\dtypes\\astype.py\", line 242, in astype_array_safe\r\n    new_values = astype_array(values, dtype, copy=copy)\r\n  File \"D:\\Develop\\AnaConda\\envs\\SURE\\lib\\site-packages\\pandas\\core\\dtypes\\astype.py\", line 187, in astype_array\r\n    values = _astype_nansafe(values, dtype, copy=copy)\r\n  File \"D:\\Develop\\AnaConda\\envs\\SURE\\lib\\site-packages\\pandas\\core\\dtypes\\astype.py\", line 138, in _astype_nansafe\r\n    return arr.astype(dtype, copy=True)\r\nValueError: invalid literal for int() with base 10: 'patch'\r\n","timestamp":"2025-04-30 20:26:07"}
